Workbook
Name bugs_per_module: 'Rate Card'!$B$66
Name expected_defect_rate: 'Rate Card'!$B$67
Name retest_rounds: 'Rate Card'!$B$68
Name bug_followup_rate: 'Rate Card'!$B$69
Name regression_scope_rate: 'Rate Card'!$B$70
Name rework_rounds: 'Rate Card'!$B$71
Name qa_round_per_module: 'Rate Card'!$B$72
Name buffer_pct: 'Rate Card'!$B$73
Name hours_per_manday: 'Rate Card'!$B$74
Name enum_correction: 'Rate Card'!$B$75
Name tc_per_req_item: 'Rate Card'!$B$76

Sheet Rate Card
A1: TEST ESTIMATE — RATE CARD (chỉ cần tune ở sheet này)
A3: 1. BASE RATE — giờ / đơn vị, tính cho level Middle (baseline). G* = chỉ định AI gen · A* = người làm · S* = support · R1 = rework
A4: Code | B4: Activity | C4: Đơn vị khối lượng | D4: S | E4: M | F4: L | G4: XL
A5: G1 | B5: Chuẩn bị input + chỉ định AI gen ticket task test | C5: ticket | D5: 0.03 | E5: 0.05 | F5: 0.065 | G5: 0.08
A6: A1 | B6: Review ticket task test AI gen | C6: ticket | D6: 0.03 | E6: 0.05 | F6: 0.065 | G6: 0.08
A7: G2 | B7: Dựng manifest + chỉ định AI gen requirement | C7: lần chạy | D7: 0.08 | E7: 0.12 | F7: 0.16 | G7: 0.2
A8: A2 | B8: Đọc hiểu + review requirement AI tạo | C8: requirement item | D8: 0.02 | E8: 0.025 | F8: 0.03 | G8: 0.04
A9: A2b | B9: Q&A phân tích yêu cầu + confirm với PO | C9: vòng Q&A | D9: 0.15 | E9: 0.25 | F9: 0.32 | G9: 0.4
A10: G3 | B10: Chỉ định AI gen test case | C10: lần chạy | D10: 0.103 | E10: 0.155 | F10: 0.207 | G10: 0.258
A11: A3 | B11: Review test case AI gen + update | C11: test case | D11: 0.026 | E11: 0.034 | F11: 0.043 | G11: 0.051
A12: S1 | B12: Setup môi trường test + account / quyền | C12: môi trường | D12: 0.5 | E12: 1 | F12: 2 | G12: 3
A13: S2 | B13: Chuẩn bị test data | C13: bộ data | D13: 0.5 | E13: 1 | F13: 1.5 | G13: 2.5
A14: A4 | B14: Execute test | C14: test case | D14: 0.065 | E14: 0.081 | F14: 0.105 | G14: 0.13
A15: G4 | B15: Cung cấp evidence + chỉ định AI log bug | C15: bug | D15: 0.015 | E15: 0.02 | F15: 0.025 | G15: 0.03
A16: A4b | B16: Review bug AI log (dedupe / severity / repro) | C16: bug | D16: 0.04 | E16: 0.05 | F16: 0.065 | G16: 0.08
... A22: A6 | B22: Review + chốt test report, cập nhật status ticket | C22: module | D22: 0.06 | E22: 0.09 | F22: 0.12 | G22: 0.15
A24: 2. LEVEL FACTOR — nhân vào base rate theo level người thực hiện
A25: Level | B25: Factor | C25: Rank | D25: Ghi chú
A26: Fresher | B26: 1.6 | C26: 1 | D26: Chưa đủ nền phản biện output AI → đọc lại nhiều vòng, dễ sót lỗi logic
A27: Junior | B27: 1.3 | C27: 2 | D27: Review được nhưng phải đối chiếu requirement từng dòng
A28: Middle | B28: 1 | C28: 3 | D28: Baseline của bảng base rate
A29: Senior | B29: 0.8 | C29: 4 | D29: Bắt sai lệch AI nhanh, quyết được điểm mờ, ít vòng lặp
A31: 3. LEVEL TỐI THIỂU THEO ACTIVITY — gán thấp hơn thì cộng phụ phí senior review. Nhạy level = 0 → Level factor cứng 1.00 (nhóm G*: giờ chỉ định AI gen không đổi theo level)
A32: Code | B32: Activity | C32: Level tối thiểu | D32: Min rank | E32: Phụ phí senior review | F32: Nhạy level? (1/0)
A33: G1 | B33: Chuẩn bị input + chỉ định AI gen ticket task test | C33: Fresher | D33: 1 | E33: 0 | F33: 0
A34: A1 | B34: Review ticket task test AI gen | C34: Junior | D34: 2 | E34: 0.2 | F34: 1
A35: G2 | B35: Dựng manifest + chỉ định AI gen requirement | C35: Middle | D35: 3 | E35: 0.3 | F35: 0
A36: A2 | B36: Đọc hiểu + review requirement AI tạo | C36: Middle | D36: 3 | E36: 0.3 | F36: 1
A37: A2b | B37: Q&A phân tích yêu cầu + confirm với PO | C37: Middle | D37: 3 | E37: 0.3 | F37: 1
A38: G3 | B38: Chỉ định AI gen test case | C38: Junior | D38: 2 | E38: 0.2 | F38: 0
A39: A3 | B39: Review test case AI gen + update | C39: Junior | D39: 2 | E39: 0.2 | F39: 1
A40: S1 | B40: Setup môi trường test + account / quyền | C40: Junior | D40: 2 | E40: 0.2 | F40: 1
A41: S2 | B41: Chuẩn bị test data | C41: Junior | D41: 2 | E41: 0.2 | F41: 1
A42: A4 | B42: Execute test | C42: Fresher | D42: 1 | E42: 0 | F42: 1
A43: G4 | B43: Cung cấp evidence + chỉ định AI log bug | C43: Junior | D43: 2 | E43: 0.2 | F43: 0
A44: A4b | B44: Review bug AI log (dedupe / severity / repro) | C44: Junior | D44: 2 | E44: 0.2 | F44: 1
... A50: A6 | B50: Review + chốt test report, cập nhật status ticket | C50: Middle | D50: 3 | E50: 0.3 | F50: 1
A52: 4. MULTIPLIER — nhập tay vào cột Multiplier của Estimate Detail (nhân dồn nếu nhiều yếu tố)
A53: Yếu tố | B53: Giá trị | C53: Ghi chú
A54: module_type_new | B54: 1 | C54: Module làm mới
...

Sheet Estimate Detail
A1: ESTIMATE DETAIL — 1 dòng = 1 activity của 1 function (ô vàng nhập tay, ô xám tự tính)
A3: Function | B3: Activity | C3: Activity name | D3: Complexity | E3: Volume | F3: Đơn vị | G3: Base rate (h) | H3: Level | I3: Level factor | J3: Multiplier | K3: Level check | L3: Adjusted (h) | M3: Note
A4: sample_module | B4: G1 | C4: =IFERROR(VLOOKUP($B4,'Rate Card'!$A$5:$C$22,2,FALSE),"") | D4: M | E4: 1 | F4: =IFERROR(VLOOKUP($B4,'Rate Card'!$A$5:$C$22,3,FALSE),"") | G4: =IFERROR(VLOOKUP($B4,'Rate Card'!$A$5:$G$22,MATCH($D4,'Rate Card'!$D$4:$G$4,0)+3,FALSE),"") | H4: Junior | I4: =IFERROR(IF(VLOOKUP($B4,'Rate Card'!$A$33:$F$50,6,FALSE)=0,1,VLOOKUP($H4,'Rate Card'!$A$26:$D$29,2,FALSE)),"") | J4: 1 | K4: =IFERROR(IF(VLOOKUP($H4,'Rate Card'!$A$26:$D$29,3,FALSE)<VLOOKUP($B4,'Rate Card'!$A$33:$F$50,4,FALSE),1+VLOOKUP($B4,'Rate Card'!$A$33:$F$50,5,FALSE),1),"") | L4: =IFERROR($E4*$G4*$I4*$J4*$K4,"") | M4: 1 ticket task test cần AI gen
A5: sample_module | B5: A1 | C5: =IFERROR(VLOOKUP($B5,'Rate Card'!$A$5:$C$22,2,FALSE),"") | D5: M | E5: 1 | F5: =IFERROR(VLOOKUP($B5,'Rate Card'!$A$5:$C$22,3,FALSE),"") | G5: =IFERROR(VLOOKUP($B5,'Rate Card'!$A$5:$G$22,MATCH($D5,'Rate Card'!$D$4:$G$4,0)+3,FALSE),"") | H5: Junior | I5: =IFERROR(IF(VLOOKUP($B5,'Rate Card'!$A$33:$F$50,6,FALSE)=0,1,VLOOKUP($H5,'Rate Card'!$A$26:$D$29,2,FALSE)),"") | J5: 1 | K5: =IFERROR(IF(VLOOKUP($H5,'Rate Card'!$A$26:$D$29,3,FALSE)<VLOOKUP($B5,'Rate Card'!$A$33:$F$50,4,FALSE),1+VLOOKUP($B5,'Rate Card'!$A$33:$F$50,5,FALSE),1),"") | L5: =IFERROR($E5*$G5*$I5*$J5*$K5,"") | M5: Review ticket AI gen
A6: sample_module | B6: G2 | C6: =IFERROR(VLOOKUP($B6,'Rate Card'!$A$5:$C$22,2,FALSE),"") | D6: M | E6: 1 | F6: =IFERROR(VLOOKUP($B6,'Rate Card'!$A$5:$C$22,3,FALSE),"") | G6: =IFERROR(VLOOKUP($B6,'Rate Card'!$A$5:$G$22,MATCH($D6,'Rate Card'!$D$4:$G$4,0)+3,FALSE),"") | H6: Middle | I6: =IFERROR(IF(VLOOKUP($B6,'Rate Card'!$A$33:$F$50,6,FALSE)=0,1,VLOOKUP($H6,'Rate Card'!$A$26:$D$29,2,FALSE)),"") | J6: 1 | K6: =IFERROR(IF(VLOOKUP($H6,'Rate Card'!$A$26:$D$29,3,FALSE)<VLOOKUP($B6,'Rate Card'!$A$33:$F$50,4,FALSE),1+VLOOKUP($B6,'Rate Card'!$A$33:$F$50,5,FALSE),1),"") | L6: =IFERROR($E6*$G6*$I6*$J6*$K6,"") | M6: 1 lần chạy /gen-requirement (gồm dựng manifest)
A7: sample_module | B7: A2 | C7: =IFERROR(VLOOKUP($B7,'Rate Card'!$A$5:$C$22,2,FALSE),"") | D7: M | E7: 12 | F7: =IFERROR(VLOOKUP($B7,'Rate Card'!$A$5:$C$22,3,FALSE),"") | G7: =IFERROR(VLOOKUP($B7,'Rate Card'!$A$5:$G$22,MATCH($D7,'Rate Card'!$D$4:$G$4,0)+3,FALSE),"") | H7: Middle | I7: =IFERROR(IF(VLOOKUP($B7,'Rate Card'!$A$33:$F$50,6,FALSE)=0,1,VLOOKUP($H7,'Rate Card'!$A$26:$D$29,2,FALSE)),"") | J7: 1 | K7: =IFERROR(IF(VLOOKUP($H7,'Rate Card'!$A$26:$D$29,3,FALSE)<VLOOKUP($B7,'Rate Card'!$A$33:$F$50,4,FALSE),1+VLOOKUP($B7,'Rate Card'!$A$33:$F$50,5,FALSE),1),"") | L7: =IFERROR($E7*$G7*$I7*$J7*$K7,"") | M7: 12 requirement item = FR + BR + VR
A8: sample_module | B8: A2b | C8: =IFERROR(VLOOKUP($B8,'Rate Card'!$A$5:$C$22,2,FALSE),"") | D8: M | E8: =qa_round_per_module | F8: =IFERROR(VLOOKUP($B8,'Rate Card'!$A$5:$C$22,3,FALSE),"") | G8: =IFERROR(VLOOKUP($B8,'Rate Card'!$A$5:$G$22,MATCH($D8,'Rate Card'!$D$4:$G$4,0)+3,FALSE),"") | H8: Middle | I8: =IFERROR(IF(VLOOKUP($B8,'Rate Card'!$A$33:$F$50,6,FALSE)=0,1,VLOOKUP($H8,'Rate Card'!$A$26:$D$29,2,FALSE)),"") | J8: 1 | K8: =IFERROR(IF(VLOOKUP($H8,'Rate Card'!$A$26:$D$29,3,FALSE)<VLOOKUP($B8,'Rate Card'!$A$33:$F$50,4,FALSE),1+VLOOKUP($B8,'Rate Card'!$A$33:$F$50,5,FALSE),1),"") | L8: =IFERROR($E8*$G8*$I8*$J8*$K8,"") | M8: Q&A + confirm PO
A9: sample_module | B9: G3 | C9: =IFERROR(VLOOKUP($B9,'Rate Card'!$A$5:$C$22,2,FALSE),"") | D9: M | E9: 1 | F9: =IFERROR(VLOOKUP($B9,'Rate Card'!$A$5:$C$22,3,FALSE),"") | G9: =IFERROR(VLOOKUP($B9,'Rate Card'!$A$5:$G$22,MATCH($D9,'Rate Card'!$D$4:$G$4,0)+3,FALSE),"") | H9: Junior | I9: =IFERROR(IF(VLOOKUP($B9,'Rate Card'!$A$33:$F$50,6,FALSE)=0,1,VLOOKUP($H9,'Rate Card'!$A$26:$D$29,2,FALSE)),"") | J9: 1 | K9: =IFERROR(IF(VLOOKUP($H9,'Rate Card'!$A$26:$D$29,3,FALSE)<VLOOKUP($B9,'Rate Card'!$A$33:$F$50,4,FALSE),1+VLOOKUP($B9,'Rate Card'!$A$33:$F$50,5,FALSE),1),"") | L9: =IFERROR($E9*$G9*$I9*$J9*$K9,"") | M9: 1 lần chạy /gen-testcase
A10: sample_module | B10: A3 | C10: =IFERROR(VLOOKUP($B10,'Rate Card'!$A$5:$C$22,2,FALSE),"") | D10: M | E10: 20 | F10: =IFERROR(VLOOKUP($B10,'Rate Card'!$A$5:$C$22,3,FALSE),"") | G10: =IFERROR(VLOOKUP($B10,'Rate Card'!$A$5:$G$22,MATCH($D10,'Rate Card'!$D$4:$G$4,0)+3,FALSE),"") | H10: Junior | I10: =IFERROR(IF(VLOOKUP($B10,'Rate Card'!$A$33:$F$50,6,FALSE)=0,1,VLOOKUP($H10,'Rate Card'!$A$26:$D$29,2,FALSE)),"") | J10: 1 | K10: =IFERROR(IF(VLOOKUP($H10,'Rate Card'!$A$26:$D$29,3,FALSE)<VLOOKUP($B10,'Rate Card'!$A$33:$F$50,4,FALSE),1+VLOOKUP($B10,'Rate Card'!$A$33:$F$50,5,FALSE),1),"") | L10: =IFERROR($E10*$G10*$I10*$J10*$K10,"") | M10: 20 test case AI gen
A11: project_level | B11: S1 | C11: =IFERROR(VLOOKUP($B11,'Rate Card'!$A$5:$C$22,2,FALSE),"") | D11: M | E11: 1 | F11: =IFERROR(VLOOKUP($B11,'Rate Card'!$A$5:$C$22,3,FALSE),"") | G11: =IFERROR(VLOOKUP($B11,'Rate Card'!$A$5:$G$22,MATCH($D11,'Rate Card'!$D$4:$G$4,0)+3,FALSE),"") | H11: Junior | I11: =IFERROR(IF(VLOOKUP($B11,'Rate Card'!$A$33:$F$50,6,FALSE)=0,1,VLOOKUP($H11,'Rate Card'!$A$26:$D$29,2,FALSE)),"") | J11: 1 | K11: =IFERROR(IF(VLOOKUP($H11,'Rate Card'!$A$26:$D$29,3,FALSE)<VLOOKUP($B11,'Rate Card'!$A$33:$F$50,4,FALSE),1+VLOOKUP($B11,'Rate Card'!$A$33:$F$50,5,FALSE),1),"") | L11: =IFERROR($E11*$G11*$I11*$J11*$K11,"") | M11: Project-level: chỉ tính 1 lần, module sau để Volume = 0
A12: project_level | B12: S2 | C12: =IFERROR(VLOOKUP($B12,'Rate Card'!$A$5:$C$22,2,FALSE),"") | D12: M | E12: 1 | F12: =IFERROR(VLOOKUP($B12,'Rate Card'!$A$5:$C$22,3,FALSE),"") | G12: =IFERROR(VLOOKUP($B12,'Rate Card'!$A$5:$G$22,MATCH($D12,'Rate Card'!$D$4:$G$4,0)+3,FALSE),"") | H12: Junior | I12: =IFERROR(IF(VLOOKUP($B12,'Rate Card'!$A$33:$F$50,6,FALSE)=0,1,VLOOKUP($H12,'Rate Card'!$A$26:$D$29,2,FALSE)),"") | J12: 1 | K12: =IFERROR(IF(VLOOKUP($H12,'Rate Card'!$A$26:$D$29,3,FALSE)<VLOOKUP($B12,'Rate Card'!$A$33:$F$50,4,FALSE),1+VLOOKUP($B12,'Rate Card'!$A$33:$F$50,5,FALSE),1),"") | L12: =IFERROR($E12*$G12*$I12*$J12*$K12,"") | M12: Project-level nếu dùng chung bộ data
A13: sample_module | B13: A4 | C13: =IFERROR(VLOOKUP($B13,'Rate Card'!$A$5:$C$22,2,FALSE),"") | D13: M | E13: =E10 | F13: =IFERROR(VLOOKUP($B13,'Rate Card'!$A$5:$C$22,3,FALSE),"") | G13: =IFERROR(VLOOKUP($B13,'Rate Card'!$A$5:$G$22,MATCH($D13,'Rate Card'!$D$4:$G$4,0)+3,FALSE),"") | H13: Junior | I13: =IFERROR(IF(VLOOKUP($B13,'Rate Card'!$A$33:$F$50,6,FALSE)=0,1,VLOOKUP($H13,'Rate Card'!$A$26:$D$29,2,FALSE)),"") | J13: 1 | K13: =IFERROR(IF(VLOOKUP($H13,'Rate Card'!$A$26:$D$29,3,FALSE)<VLOOKUP($B13,'Rate Card'!$A$33:$F$50,4,FALSE),1+VLOOKUP($B13,'Rate Card'!$A$33:$F$50,5,FALSE),1),"") | L13: =IFERROR($E13*$G13*$I13*$J13*$K13,"") | M13: Execute = số TC ở dòng A3
A14: sample_module | B14: G4 | C14: =IFERROR(VLOOKUP($B14,'Rate Card'!$A$5:$C$22,2,FALSE),"") | D14: M | E14: =bugs_per_module | F14: =IFERROR(VLOOKUP($B14,'Rate Card'!$A$5:$C$22,3,FALSE),"") | G14: =IFERROR(VLOOKUP($B14,'Rate Card'!$A$5:$G$22,MATCH($D14,'Rate Card'!$D$4:$G$4,0)+3,FALSE),"") | H14: Junior | I14: =IFERROR(IF(VLOOKUP($B14,'Rate Card'!$A$33:$F$50,6,FALSE)=0,1,VLOOKUP($H14,'Rate Card'!$A$26:$D$29,2,FALSE)),"") | J14: 1 | K14: =IFERROR(IF(VLOOKUP($H14,'Rate Card'!$A$26:$D$29,3,FALSE)<VLOOKUP($B14,'Rate Card'!$A$33:$F$50,4,FALSE),1+VLOOKUP($B14,'Rate Card'!$A$33:$F$50,5,FALSE),1),"") | L14: =IFERROR($E14*$G14*$I14*$J14*$K14,"") | M14: Bug dự kiến / module (UI test)
A15: sample_module | B15: A4b | C15: =IFERROR(VLOOKUP($B15,'Rate Card'!$A$5:$C$22,2,FALSE),"") | D15: M | E15: =E14 | F15: =IFERROR(VLOOKUP($B15,'Rate Card'!$A$5:$C$22,3,FALSE),"") | G15: =IFERROR(VLOOKUP($B15,'Rate Card'!$A$5:$G$22,MATCH($D15,'Rate Card'!$D$4:$G$4,0)+3,FALSE),"") | H15: Junior | I15: =IFERROR(IF(VLOOKUP($B15,'Rate Card'!$A$33:$F$50,6,FALSE)=0,1,VLOOKUP($H15,'Rate Card'!$A$26:$D$29,2,FALSE)),"") | J15: 1 | K15: =IFERROR(IF(VLOOKUP($H15,'Rate Card'!$A$26:$D$29,3,FALSE)<VLOOKUP($B15,'Rate Card'!$A$33:$F$50,4,FALSE),1+VLOOKUP($B15,'Rate Card'!$A$33:$F$50,5,FALSE),1),"") | L15: =IFERROR($E15*$G15*$I15*$J15*$K15,"") | M15: Review đúng số bug AI đã log
A16: sample_module | B16: A5 | C16: =IFERROR(VLOOKUP($B16,'Rate Card'!$A$5:$C$22,2,FALSE),"") | D16: M | E16: =E15*retest_rounds | F16: =IFERROR(VLOOKUP($B16,'Rate Card'!$A$5:$C$22,3,FALSE),"") | G16: =IFERROR(VLOOKUP($B16,'Rate Card'!$A$5:$G$22,MATCH($D16,'Rate Card'!$D$4:$G$4,0)+3,FALSE),"") | H16: Junior | I16: =IFERROR(IF(VLOOKUP($B16,'Rate Card'!$A$33:$F$50,6,FALSE)=0,1,VLOOKUP($H16,'Rate Card'!$A$26:$D$29,2,FALSE)),"") | J16: 1 | K16: =IFERROR(IF(VLOOKUP($H16,'Rate Card'!$A$26:$D$29,3,FALSE)<VLOOKUP($B16,'Rate Card'!$A$33:$F$50,4,FALSE),1+VLOOKUP($B16,'Rate Card'!$A$33:$F$50,5,FALSE),1),"") | L16: =IFERROR($E16*$G16*$I16*$J16*$K16,"") | M16: Verify bug × số vòng retest
A17: sample_module | B17: S3 | C17: =IFERROR(VLOOKUP($B17,'Rate Card'!$A$5:$C$22,2,FALSE),"") | D17: M | E17: =E15*bug_followup_rate | F17: =IFERROR(VLOOKUP($B17,'Rate Card'!$A$5:$C$22,3,FALSE),"") | G17: =IFERROR(VLOOKUP($B17,'Rate Card'!$A$5:$G$22,MATCH($D17,'Rate Card'!$D$4:$G$4,0)+3,FALSE),"") | H17: Junior | I17: =IFERROR(IF(VLOOKUP($B17,'Rate Card'!$A$33:$F$50,6,FALSE)=0,1,VLOOKUP($H17,'Rate Card'!$A$26:$D$29,2,FALSE)),"") | J17: 1 | K17: =IFERROR(IF(VLOOKUP($H17,'Rate Card'!$A$26:$D$29,3,FALSE)<VLOOKUP($B17,'Rate Card'!$A$33:$F$50,4,FALSE),1+VLOOKUP($B17,'Rate Card'!$A$33:$F$50,5,FALSE),1),"") | L17: =IFERROR($E17*$G17*$I17*$J17*$K17,"") | M17: Bug bị reject / reopen
A18: sample_module | B18: S4 | C18: =IFERROR(VLOOKUP($B18,'Rate Card'!$A$5:$C$22,2,FALSE),"") | D18: M | E18: =E13*regression_scope_rate | F18: =IFERROR(VLOOKUP($B18,'Rate Card'!$A$5:$C$22,3,FALSE),"") | G18: =IFERROR(VLOOKUP($B18,'Rate Card'!$A$5:$G$22,MATCH($D18,'Rate Card'!$D$4:$G$4,0)+3,FALSE),"") | H18: Junior | I18: =IFERROR(IF(VLOOKUP($B18,'Rate Card'!$A$33:$F$50,6,FALSE)=0,1,VLOOKUP($H18,'Rate Card'!$A$26:$D$29,2,FALSE)),"") | J18: 1 | K18: =IFERROR(IF(VLOOKUP($H18,'Rate Card'!$A$26:$D$29,3,FALSE)<VLOOKUP($B18,'Rate Card'!$A$33:$F$50,4,FALSE),1+VLOOKUP($B18,'Rate Card'!$A$33:$F$50,5,FALSE),1),"") | L18: =IFERROR($E18*$G18*$I18*$J18*$K18,"") | M18: Regression vùng ảnh hưởng
A19: sample_module | B19: R1 | C19: =IFERROR(VLOOKUP($B19,'Rate Card'!$A$5:$C$22,2,FALSE),"") | D19: M | E19: =rework_rounds | F19: =IFERROR(VLOOKUP($B19,'Rate Card'!$A$5:$C$22,3,FALSE),"") | G19: =IFERROR(VLOOKUP($B19,'Rate Card'!$A$5:$G$22,MATCH($D19,'Rate Card'!$D$4:$G$4,0)+3,FALSE),"") | H19: Middle | I19: =IFERROR(IF(VLOOKUP($B19,'Rate Card'!$A$33:$F$50,6,FALSE)=0,1,VLOOKUP($H19,'Rate Card'!$A$26:$D$29,2,FALSE)),"") | J19: 1 | K19: =IFERROR(IF(VLOOKUP($H19,'Rate Card'!$A$26:$D$29,3,FALSE)<VLOOKUP($B19,'Rate Card'!$A$33:$F$50,4,FALSE),1+VLOOKUP($B19,'Rate Card'!$A$33:$F$50,5,FALSE),1),"") | L19: =IFERROR($E19*$G19*$I19*$J19*$K19,"") | M19: Rework output AI / requirement đổi
A20: sample_module | B20: G5 | C20: =IFERROR(VLOOKUP($B20,'Rate Card'!$A$5:$C$22,2,FALSE),"") | D20: M | E20: 1 | F20: =IFERROR(VLOOKUP($B20,'Rate Card'!$A$5:$C$22,3,FALSE),"") | G20: =IFERROR(VLOOKUP($B20,'Rate Card'!$A$5:$G$22,MATCH($D20,'Rate Card'!$D$4:$G$4,0)+3,FALSE),"") | H20: Junior | I20: =IFERROR(IF(VLOOKUP($B20,'Rate Card'!$A$33:$F$50,6,FALSE)=0,1,VLOOKUP($H20,'Rate Card'!$A$26:$D$29,2,FALSE)),"") | J20: 1 | K20: =IFERROR(IF(VLOOKUP($H20,'Rate Card'!$A$26:$D$29,3,FALSE)<VLOOKUP($B20,'Rate Card'!$A$33:$F$50,4,FALSE),1+VLOOKUP($B20,'Rate Card'!$A$33:$F$50,5,FALSE),1),"") | L20: =IFERROR($E20*$G20*$I20*$J20*$K20,"") | M20: Chỉ định AI gen test report
A21: sample_module | B21: A6 | C21: =IFERROR(VLOOKUP($B21,'Rate Card'!$A$5:$C$22,2,FALSE),"") | D21: M | E21: 1 | F21: =IFERROR(VLOOKUP($B21,'Rate Card'!$A$5:$C$22,3,FALSE),"") | G21: =IFERROR(VLOOKUP($B21,'Rate Card'!$A$5:$G$22,MATCH($D21,'Rate Card'!$D$4:$G$4,0)+3,FALSE),"") | H21: Middle | I21: =IFERROR(IF(VLOOKUP($B21,'Rate Card'!$A$33:$F$50,6,FALSE)=0,1,VLOOKUP($H21,'Rate Card'!$A$26:$D$29,2,FALSE)),"") | J21: 1 | K21: =IFERROR(IF(VLOOKUP($H21,'Rate Card'!$A$26:$D$29,3,FALSE)<VLOOKUP($B21,'Rate Card'!$A$33:$F$50,4,FALSE),1+VLOOKUP($B21,'Rate Card'!$A$33:$F$50,5,FALSE),1),"") | L21: =IFERROR($E21*$G21*$I21*$J21*$K21,"") | M21: Chốt report + cập nhật status ticket
C22: =IFERROR(VLOOKUP($B22,'Rate Card'!$A$5:$C$22,2,FALSE),"") | F22: =IFERROR(VLOOKUP($B22,'Rate Card'!$A$5:$C$22,3,FALSE),"") | G22: =IFERROR(VLOOKUP($B22,'Rate Card'!$A$5:$G$22,MATCH($D22,'Rate Card'!$D$4:$G$4,0)+3,FALSE),"") | I22: =IFERROR(IF(VLOOKUP($B22,'Rate Card'!$A$33:$F$50,6,FALSE)=0,1,VLOOKUP($H22,'Rate Card'!$A$26:$D$29,2,FALSE)),"") | K22: =IFERROR(IF(VLOOKUP($H22,'Rate Card'!$A$26:$D$29,3,FALSE)<VLOOKUP($B22,'Rate Card'!$A$33:$F$50,4,FALSE),1+VLOOKUP($B22,'Rate Card'!$A$33:$F$50,5,FALSE),1),"") | L22: =IFERROR($E22*$G22*$I22*$J22*$K22,"")
C23: =IFERROR(VLOOKUP($B23,'Rate Card'!$A$5:$C$22,2,FALSE),"") | F23: =IFERROR(VLOOKUP($B23,'Rate Card'!$A$5:$C$22,3,FALSE),"") | G23: =IFERROR(VLOOKUP($B23,'Rate Card'!$A$5:$G$22,MATCH($D23,'Rate Card'!$D$4:$G$4,0)+3,FALSE),"") | I23: =IFERROR(IF(VLOOKUP($B23,'Rate Card'!$A$33:$F$50,6,FALSE)=0,1,VLOOKUP($H23,'Rate Card'!$A$26:$D$29,2,FALSE)),"") | K23: =IFERROR(IF(VLOOKUP($H23,'Rate Card'!$A$26:$D$29,3,FALSE)<VLOOKUP($B23,'Rate Card'!$A$33:$F$50,4,FALSE),1+VLOOKUP($B23,'Rate Card'!$A$33:$F$50,5,FALSE),1),"") | L23: =IFERROR($E23*$G23*$I23*$J23*$K23,"")
C24: =IFERROR(VLOOKUP($B24,'Rate Card'!$A$5:$C$22,2,FALSE),"") | F24: =IFERROR(VLOOKUP($B24,'Rate Card'!$A$5:$C$22,3,FALSE),"") | G24: =IFERROR(VLOOKUP($B24,'Rate Card'!$A$5:$G$22,MATCH($D24,'Rate Card'!$D$4:$G$4,0)+3,FALSE),"") | I24: =IFERROR(IF(VLOOKUP($B24,'Rate Card'!$A$33:$F$50,6,FALSE)=0,1,VLOOKUP($H24,'Rate Card'!$A$26:$D$29,2,FALSE)),"") | K24: =IFERROR(IF(VLOOKUP($H24,'Rate Card'!$A$26:$D$29,3,FALSE)<VLOOKUP($B24,'Rate Card'!$A$33:$F$50,4,FALSE),1+VLOOKUP($B24,'Rate Card'!$A$33:$F$50,5,FALSE),1),"") | L24: =IFERROR($E24*$G24*$I24*$J24*$K24,"")
C25: =IFERROR(VLOOKUP($B25,'Rate Card'!$A$5:$C$22,2,FALSE),"") | F25: =IFERROR(VLOOKUP($B25,'Rate Card'!$A$5:$C$22,3,FALSE),"") | G25: =IFERROR(VLOOKUP($B25,'Rate Card'!$A$5:$G$22,MATCH($D25,'Rate Card'!$D$4:$G$4,0)+3,FALSE),"") | I25: =IFERROR(IF(VLOOKUP($B25,'Rate Card'!$A$33:$F$50,6,FALSE)=0,1,VLOOKUP($H25,'Rate Card'!$A$26:$D$29,2,FALSE)),"") | K25: =IFERROR(IF(VLOOKUP($H25,'Rate Card'!$A$26:$D$29,3,FALSE)<VLOOKUP($B25,'Rate Card'!$A$33:$F$50,4,FALSE),1+VLOOKUP($B25,'Rate Card'!$A$33:$F$50,5,FALSE),1),"") | L25: =IFERROR($E25*$G25*$I25*$J25*$K25,"")
C26: =IFERROR(VLOOKUP($B26,'Rate Card'!$A$5:$C$22,2,FALSE),"") | F26: =IFERROR(VLOOKUP($B26,'Rate Card'!$A$5:$C$22,3,FALSE),"") | G26: =IFERROR(VLOOKUP($B26,'Rate Card'!$A$5:$G$22,MATCH($D26,'Rate Card'!$D$4:$G$4,0)+3,FALSE),"") | I26: =IFERROR(IF(VLOOKUP($B26,'Rate Card'!$A$33:$F$50,6,FALSE)=0,1,VLOOKUP($H26,'Rate Card'!$A$26:$D$29,2,FALSE)),"") | K26: =IFERROR(IF(VLOOKUP($H26,'Rate Card'!$A$26:$D$29,3,FALSE)<VLOOKUP($B26,'Rate Card'!$A$33:$F$50,4,FALSE),1+VLOOKUP($B26,'Rate Card'!$A$33:$F$50,5,FALSE),1),"") | L26: =IFERROR($E26*$G26*$I26*$J26*$K26,"")
C27: =IFERROR(VLOOKUP($B27,'Rate Card'!$A$5:$C$22,2,FALSE),"") | F27: =IFERROR(VLOOKUP($B27,'Rate Card'!$A$5:$C$22,3,FALSE),"") | G27: =IFERROR(VLOOKUP($B27,'Rate Card'!$A$5:$G$22,MATCH($D27,'Rate Card'!$D$4:$G$4,0)+3,FALSE),"") | I27: =IFERROR(IF(VLOOKUP($B27,'Rate Card'!$A$33:$F$50,6,FALSE)=0,1,VLOOKUP($H27,'Rate Card'!$A$26:$D$29,2,FALSE)),"") | K27: =IFERROR(IF(VLOOKUP($H27,'Rate Card'!$A$26:$D$29,3,FALSE)<VLOOKUP($B27,'Rate Card'!$A$33:$F$50,4,FALSE),1+VLOOKUP($B27,'Rate Card'!$A$33:$F$50,5,FALSE),1),"") | L27: =IFERROR($E27*$G27*$I27*$J27*$K27,"")
C28: =IFERROR(VLOOKUP($B28,'Rate Card'!$A$5:$C$22,2,FALSE),"") | F28: =IFERROR(VLOOKUP($B28,'Rate Card'!$A$5:$C$22,3,FALSE),"") | G28: =IFERROR(VLOOKUP($B28,'Rate Card'!$A$5:$G$22,MATCH($D28,'Rate Card'!$D$4:$G$4,0)+3,FALSE),"") | I28: =IFERROR(IF(VLOOKUP($B28,'Rate Card'!$A$33:$F$50,6,FALSE)=0,1,VLOOKUP($H28,'Rate Card'!$A$26:$D$29,2,FALSE)),"") | K28: =IFERROR(IF(VLOOKUP($H28,'Rate Card'!$A$26:$D$29,3,FALSE)<VLOOKUP($B28,'Rate Card'!$A$33:$F$50,4,FALSE),1+VLOOKUP($B28,'Rate Card'!$A$33:$F$50,5,FALSE),1),"") | L28: =IFERROR($E28*$G28*$I28*$J28*$K28,"")
C29: =IFERROR(VLOOKUP($B29,'Rate Card'!$A$5:$C$22,2,FALSE),"") | F29: =IFERROR(VLOOKUP($B29,'Rate Card'!$A$5:$C$22,3,FALSE),"") | G29: =IFERROR(VLOOKUP($B29,'Rate Card'!$A$5:$G$22,MATCH($D29,'Rate Card'!$D$4:$G$4,0)+3,FALSE),"") | I29: =IFERROR(IF(VLOOKUP($B29,'Rate Card'!$A$33:$F$50,6,FALSE)=0,1,VLOOKUP($H29,'Rate Card'!$A$26:$D$29,2,FALSE)),"") | K29: =IFERROR(IF(VLOOKUP($H29,'Rate Card'!$A$26:$D$29,3,FALSE)<VLOOKUP($B29,'Rate Card'!$A$33:$F$50,4,FALSE),1+VLOOKUP($B29,'Rate Card'!$A$33:$F$50,5,FALSE),1),"") | L29: =IFERROR($E29*$G29*$I29*$J29*$K29,"")
C30: =IFERROR(VLOOKUP($B30,'Rate Card'!$A$5:$C$22,2,FALSE),"") | F30: =IFERROR(VLOOKUP($B30,'Rate Card'!$A$5:$C$22,3,FALSE),"") | G30: =IFERROR(VLOOKUP($B30,'Rate Card'!$A$5:$G$22,MATCH($D30,'Rate Card'!$D$4:$G$4,0)+3,FALSE),"") | I30: =IFERROR(IF(VLOOKUP($B30,'Rate Card'!$A$33:$F$50,6,FALSE)=0,1,VLOOKUP($H30,'Rate Card'!$A$26:$D$29,2,FALSE)),"") | K30: =IFERROR(IF(VLOOKUP($H30,'Rate Card'!$A$26:$D$29,3,FALSE)<VLOOKUP($B30,'Rate Card'!$A$33:$F$50,4,FALSE),1+VLOOKUP($B30,'Rate Card'!$A$33:$F$50,5,FALSE),1),"") | L30: =IFERROR($E30*$G30*$I30*$J30*$K30,"")
C31: =IFERROR(VLOOKUP($B31,'Rate Card'!$A$5:$C$22,2,FALSE),"") | F31: =IFERROR(VLOOKUP($B31,'Rate Card'!$A$5:$C$22,3,FALSE),"") | G31: =IFERROR(VLOOKUP($B31,'Rate Card'!$A$5:$G$22,MATCH($D31,'Rate Card'!$D$4:$G$4,0)+3,FALSE),"") | I31: =IFERROR(IF(VLOOKUP($B31,'Rate Card'!$A$33:$F$50,6,FALSE)=0,1,VLOOKUP($H31,'Rate Card'!$A$26:$D$29,2,FALSE)),"") | K31: =IFERROR(IF(VLOOKUP($H31,'Rate Card'!$A$26:$D$29,3,FALSE)<VLOOKUP($B31,'Rate Card'!$A$33:$F$50,4,FALSE),1+VLOOKUP($B31,'Rate Card'!$A$33:$F$50,5,FALSE),1),"") | L31: =IFERROR($E31*$G31*$I31*$J31*$K31,"")
C32: =IFERROR(VLOOKUP($B32,'Rate Card'!$A$5:$C$22,2,FALSE),"") | F32: =IFERROR(VLOOKUP($B32,'Rate Card'!$A$5:$C$22,3,FALSE),"") | G32: =IFERROR(VLOOKUP($B32,'Rate Card'!$A$5:$G$22,MATCH($D32,'Rate Card'!$D$4:$G$4,0)+3,FALSE),"") | I32: =IFERROR(IF(VLOOKUP($B32,'Rate Card'!$A$33:$F$50,6,FALSE)=0,1,VLOOKUP($H32,'Rate Card'!$A$26:$D$29,2,FALSE)),"") | K32: =IFERROR(IF(VLOOKUP($H32,'Rate Card'!$A$26:$D$29,3,FALSE)<VLOOKUP($B32,'Rate Card'!$A$33:$F$50,4,FALSE),1+VLOOKUP($B32,'Rate Card'!$A$33:$F$50,5,FALSE),1),"") | L32: =IFERROR($E32*$G32*$I32*$J32*$K32,"")
C33: =IFERROR(VLOOKUP($B33,'Rate Card'!$A$5:$C$22,2,FALSE),"") | F33: =IFERROR(VLOOKUP($B33,'Rate Card'!$A$5:$C$22,3,FALSE),"") | G33: =IFERROR(VLOOKUP($B33,'Rate Card'!$A$5:$G$22,MATCH($D33,'Rate Card'!$D$4:$G$4,0)+3,FALSE),"") | I33: =IFERROR(IF(VLOOKUP($B33,'Rate Card'!$A$33:$F$50,6,FALSE)=0,1,VLOOKUP($H33,'Rate Card'!$A$26:$D$29,2,FALSE)),"") | K33: =IFERROR(IF(VLOOKUP($H33,'Rate Card'!$A$26:$D$29,3,FALSE)<VLOOKUP($B33,'Rate Card'!$A$33:$F$50,4,FALSE),1+VLOOKUP($B33,'Rate Card'!$A$33:$F$50,5,FALSE),1),"") | L33: =IFERROR($E33*$G33*$I33*$J33*$K33,"")
... C200: =IFERROR(VLOOKUP($B200,'Rate Card'!$A$5:$C$22,2,FALSE),"") | F200: =IFERROR(VLOOKUP($B200,'Rate Card'!$A$5:$C$22,3,FALSE),"") | G200: =IFERROR(VLOOKUP($B200,'Rate Card'!$A$5:$G$22,MATCH($D200,'Rate Card'!$D$4:$G$4,0)+3,FALSE),"") | I200: =IFERROR(IF(VLOOKUP($B200,'Rate Card'!$A$33:$F$50,6,FALSE)=0,1,VLOOKUP($H200,'Rate Card'!$A$26:$D$29,2,FALSE)),"") | K200: =IFERROR(IF(VLOOKUP($H200,'Rate Card'!$A$26:$D$29,3,FALSE)<VLOOKUP($B200,'Rate Card'!$A$33:$F$50,4,FALSE),1+VLOOKUP($B200,'Rate Card'!$A$33:$F$50,5,FALSE),1),"") | L200: =IFERROR($E200*$G200*$I200*$J200*$K200,"")
L202: =SUM(L4:L200) | M202: Tổng chưa buffer

Sheet Estimate Summary
A1: ESTIMATE SUMMARY — effort theo hoạt động, theo level, theo function
A3: 1. EFFORT THEO HOẠT ĐỘNG
A4: Code | B4: Activity | C4: Manhour | D4: % tổng
A5: G1 | B5: Chuẩn bị input + chỉ định AI gen ticket task test | C5: =SUMIF('Estimate Detail'!$B$4:$B$200,$A5,'Estimate Detail'!$L$4:$L$200) | D5: =IFERROR(C5/$C$23,"")
A6: A1 | B6: Review ticket task test AI gen | C6: =SUMIF('Estimate Detail'!$B$4:$B$200,$A6,'Estimate Detail'!$L$4:$L$200) | D6: =IFERROR(C6/$C$23,"")
A7: G2 | B7: Dựng manifest + chỉ định AI gen requirement | C7: =SUMIF('Estimate Detail'!$B$4:$B$200,$A7,'Estimate Detail'!$L$4:$L$200) | D7: =IFERROR(C7/$C$23,"")
A8: A2 | B8: Đọc hiểu + review requirement AI tạo | C8: =SUMIF('Estimate Detail'!$B$4:$B$200,$A8,'Estimate Detail'!$L$4:$L$200) | D8: =IFERROR(C8/$C$23,"")
A9: A2b | B9: Q&A phân tích yêu cầu + confirm với PO | C9: =SUMIF('Estimate Detail'!$B$4:$B$200,$A9,'Estimate Detail'!$L$4:$L$200) | D9: =IFERROR(C9/$C$23,"")
A10: G3 | B10: Chỉ định AI gen test case | C10: =SUMIF('Estimate Detail'!$B$4:$B$200,$A10,'Estimate Detail'!$L$4:$L$200) | D10: =IFERROR(C10/$C$23,"")
A11: A3 | B11: Review test case AI gen + update | C11: =SUMIF('Estimate Detail'!$B$4:$B$200,$A11,'Estimate Detail'!$L$4:$L$200) | D11: =IFERROR(C11/$C$23,"")
A12: S1 | B12: Setup môi trường test + account / quyền | C12: =SUMIF('Estimate Detail'!$B$4:$B$200,$A12,'Estimate Detail'!$L$4:$L$200) | D12: =IFERROR(C12/$C$23,"")
A13: S2 | B13: Chuẩn bị test data | C13: =SUMIF('Estimate Detail'!$B$4:$B$200,$A13,'Estimate Detail'!$L$4:$L$200) | D13: =IFERROR(C13/$C$23,"")
A14: A4 | B14: Execute test | C14: =SUMIF('Estimate Detail'!$B$4:$B$200,$A14,'Estimate Detail'!$L$4:$L$200) | D14: =IFERROR(C14/$C$23,"")
A15: G4 | B15: Cung cấp evidence + chỉ định AI log bug | C15: =SUMIF('Estimate Detail'!$B$4:$B$200,$A15,'Estimate Detail'!$L$4:$L$200) | D15: =IFERROR(C15/$C$23,"")
A16: A4b | B16: Review bug AI log (dedupe / severity / repro) | C16: =SUMIF('Estimate Detail'!$B$4:$B$200,$A16,'Estimate Detail'!$L$4:$L$200) | D16: =IFERROR(C16/$C$23,"")
... A22: A6 | B22: Review + chốt test report, cập nhật status ticket | C22: =SUMIF('Estimate Detail'!$B$4:$B$200,$A22,'Estimate Detail'!$L$4:$L$200) | D22: =IFERROR(C22/$C$23,"")
B23: Subtotal (chưa buffer) | C23: =SUM(C5:C22)
B24: Buffer risk | C24: =C23*buffer_pct
B25: TOTAL manhour | C25: =C23+C24
B26: TOTAL manday | C26: =C25/hours_per_manday
A28: 2. EFFORT THEO LEVEL NHÂN SỰ (không tính số người — chỉ level)
A29: Level | B29: Manhour | C29: Manday (chưa buffer) | D29: Manday (có buffer)
A30: Fresher | B30: =SUMIF('Estimate Detail'!$H$4:$H$200,$A30,'Estimate Detail'!$L$4:$L$200) | C30: =B30/hours_per_manday | D30: =B30*(1+buffer_pct)/hours_per_manday
A31: Junior | B31: =SUMIF('Estimate Detail'!$H$4:$H$200,$A31,'Estimate Detail'!$L$4:$L$200) | C31: =B31/hours_per_manday | D31: =B31*(1+buffer_pct)/hours_per_manday
A32: Middle | B32: =SUMIF('Estimate Detail'!$H$4:$H$200,$A32,'Estimate Detail'!$L$4:$L$200) | C32: =B32/hours_per_manday | D32: =B32*(1+buffer_pct)/hours_per_manday
A33: Senior | B33: =SUMIF('Estimate Detail'!$H$4:$H$200,$A33,'Estimate Detail'!$L$4:$L$200) | C33: =B33/hours_per_manday | D33: =B33*(1+buffer_pct)/hours_per_manday
A34: Tổng | B34: =SUM(B30:B33) | C34: =SUM(C30:C33) | D34: =SUM(D30:D33)
A36: 3. EFFORT THEO FUNCTION / MODULE
A37: Function | B37: Manhour | C37: Manday (có buffer)
A38: sample_module | B38: =IFERROR(SUMIF('Estimate Detail'!$A$4:$A$200,$A38,'Estimate Detail'!$L$4:$L$200),"") | C38: =IFERROR(B38*(1+buffer_pct)/hours_per_manday,"")
A39: project_level | B39: =IFERROR(SUMIF('Estimate Detail'!$A$4:$A$200,$A39,'Estimate Detail'!$L$4:$L$200),"") | C39: =IFERROR(B39*(1+buffer_pct)/hours_per_manday,"")
B40: =IFERROR(SUMIF('Estimate Detail'!$A$4:$A$200,$A40,'Estimate Detail'!$L$4:$L$200),"") | C40: =IFERROR(B40*(1+buffer_pct)/hours_per_manday,"")
B41: =IFERROR(SUMIF('Estimate Detail'!$A$4:$A$200,$A41,'Estimate Detail'!$L$4:$L$200),"") | C41: =IFERROR(B41*(1+buffer_pct)/hours_per_manday,"")
B42: =IFERROR(SUMIF('Estimate Detail'!$A$4:$A$200,$A42,'Estimate Detail'!$L$4:$L$200),"") | C42: =IFERROR(B42*(1+buffer_pct)/hours_per_manday,"")
B43: =IFERROR(SUMIF('Estimate Detail'!$A$4:$A$200,$A43,'Estimate Detail'!$L$4:$L$200),"") | C43: =IFERROR(B43*(1+buffer_pct)/hours_per_manday,"")
B44: =IFERROR(SUMIF('Estimate Detail'!$A$4:$A$200,$A44,'Estimate Detail'!$L$4:$L$200),"") | C44: =IFERROR(B44*(1+buffer_pct)/hours_per_manday,"")
B45: =IFERROR(SUMIF('Estimate Detail'!$A$4:$A$200,$A45,'Estimate Detail'!$L$4:$L$200),"") | C45: =IFERROR(B45*(1+buffer_pct)/hours_per_manday,"")
B46: =IFERROR(SUMIF('Estimate Detail'!$A$4:$A$200,$A46,'Estimate Detail'!$L$4:$L$200),"") | C46: =IFERROR(B46*(1+buffer_pct)/hours_per_manday,"")
B47: =IFERROR(SUMIF('Estimate Detail'!$A$4:$A$200,$A47,'Estimate Detail'!$L$4:$L$200),"") | C47: =IFERROR(B47*(1+buffer_pct)/hours_per_manday,"")
B48: =IFERROR(SUMIF('Estimate Detail'!$A$4:$A$200,$A48,'Estimate Detail'!$L$4:$L$200),"") | C48: =IFERROR(B48*(1+buffer_pct)/hours_per_manday,"")
...

Sheet Assumptions & Risks
A1: ASSUMPTIONS & RISKS — mọi giả định làm nên con số estimate
A3: # | B3: Loại | C3: Nội dung | D3: Ảnh hưởng tới estimate | E3: Độ tin cậy | F3: Nguồn
A4: 1 | B4: Assumption | C4: Base rate là giờ của level Middle; level khác quy đổi qua Level factor | D4: Toàn bộ cột Adjusted (h) | E4: Cao | F4: Rate Card mục 1 + 2
A5: 2 | B5: Assumption | C5: Base rate calibrate 2026-08-18 từ 1 điểm dữ liệu (phản hồi QA: execute ~5 phút/case) + 37 TC đếm thật của event_edit_schedule — CHƯA có log giờ thực tế theo từng activity | D5: Sai tỷ lệ tổng effort nếu team nhanh/chậm hơn mốc này | E5: Thấp | F5: references/estimation-model.md §6
A6: 3 | B6: Assumption | C6: QA tự chạy skill AI → có tính G1..G5; nếu BA/dev chạy thì để Volume = 0 | D6: Toàn bộ nhóm G | E6: Trung bình | F6: manifest: context.ai_driver
A7: 4 | B7: Assumption | C7: Giờ họp / communication nằm trong buffer 15%, không có dòng riêng | D7: buffer_pct | E7: Trung bình | F7: Rate Card mục 5
A8: 5 | B8: Assumption | C8: S1 / S2 là project-level — chỉ tính 1 lần ở Function = project_level | D8: Không nhân lặp theo từng module | E8: Cao | F8: SKILL.md §10.2
A9: 6 | B9: Assumption | C9: Bug dự kiến = bugs_per_module (1 bug / chức năng, phase UI test); follow-up = bug × bug_followup_rate | D9: Volume G4 / A4b / A5 / S3 | E9: Trung bình | F9: Rate Card mục 5
A10: 7 | B10: Open point | C10: Chưa có testcase_draft.csv → volume TC suy từ (FR+BR+VR) × tc_per_req_item | D10: Volume A3 / A4 → kéo theo G4 / A4b / A5 / S3 / S4 | E10: Thấp | F10: references/estimation-model.md §3
A11: 8 | B11: Risk | C11: Multiplier requirement_unstable / ui_japanese / cross_module đã bị VÔ HIỆU (=1.00) vì đếm trùng với tiêu chí chấm complexity — không tự bật lại nếu chưa bỏ tiêu chí tương ứng ở mục 6 | D11: Tránh nhân dồn 2 lần cùng 1 yếu tố | E11: Cao | F11: Rate Card mục 4 + mục 6
A12: 9 | B12: Risk | C12: Gán level thấp hơn mức tối thiểu của activity → cộng phụ phí senior review | D12: Cột Level check tự nhận hệ số > 1 | E12: Cao | F12: Rate Card mục 3
A13: 10 | B13: Risk | C13: Requirement chưa ổn định (open_points >= 5) → vòng Q&A và rework nhiều hơn 1 | D13: Volume A2b và R1 tăng | E13: Trung bình | F13: open_points.md của module
A14: 11 | B14: Risk | C14: Prompt/skill AI còn ở mức pilot → rework_rounds = 2 và multiplier 1.30 | D14: Volume R1 + toàn bộ multiplier | E14: Trung bình | F14: manifest: context.ai_output_maturity
A15: 12
A16: 13
A17: 14
A18: 15
A19: 16
A20: 17
A21: 18
A22: 19
A23: 20
A24: 21
A25: 22
A26: 23
